{
  "summary": {
    "total_tests": 27,
    "passed_tests": 0,
    "failed_tests": 27,
    "total_duration": 0.015836,
    "timestamp": "2025-08-13T13:10:37.035486"
  },
  "results": {
    "test_geo_download": {
      "test_id": "test_geo_download",
      "success": false,
      "error_message": "Test setup/execution failed: 1 validation error for ChatBedrock\n  Value error, Error raised by service:\n\nIf providing credentials, both aws_access_key_id and aws_secret_access_key must be specified. [type=value_error, input_value={'model_id': 'us.anthropi...se_converse_api': False}, input_type=dict]\n    For further information visit https://errors.pydantic.dev/2.11/v/value_error\nTraceback (most recent call last):\n  File \"/Users/tyo/GITHUB/lobster/tests/run_integration_tests.py\", line 105, in run_single_test\n    client = AgentClient(\n        workspace_path=workspace_dir,\n    ...<9 lines>...\n    }\n    )\n  File \"/Users/tyo/GITHUB/lobster/lobster/core/client.py\", line 62, in __init__\n    self.graph = create_bioinformatics_graph(\n                 ~~~~~~~~~~~~~~~~~~~~~~~~~~~^\n        data_manager=self.data_manager,\n        ^^^^^^^^^^^^^^^^^^^^^^^^^^^^^^^\n    ...<2 lines>...\n        manual_model_params=manual_model_params  # Placeholder for future manual model params\n        ^^^^^^^^^^^^^^^^^^^^^^^^^^^^^^^^^^^^^^^^^^^^^^^^^^^^^^^^^^^^^^^^^^^^^^^^^^^^^^^^^^^^^\n    )\n    ^\n  File \"/Users/tyo/GITHUB/lobster/lobster/agents/graph.py\", line 41, in create_bioinformatics_graph\n    supervisor_model = ChatBedrock(**model_params)\n  File \"/Users/tyo/GITHUB/lobster/.venv/lib/python3.13/site-packages/langchain_core/load/serializable.py\", line 130, in __init__\n    super().__init__(*args, **kwargs)\n    ~~~~~~~~~~~~~~~~^^^^^^^^^^^^^^^^^\n  File \"/Users/tyo/GITHUB/lobster/.venv/lib/python3.13/site-packages/pydantic/main.py\", line 253, in __init__\n    validated_self = self.__pydantic_validator__.validate_python(data, self_instance=self)\npydantic_core._pydantic_core.ValidationError: 1 validation error for ChatBedrock\n  Value error, Error raised by service:\n\nIf providing credentials, both aws_access_key_id and aws_secret_access_key must be specified. [type=value_error, input_value={'model_id': 'us.anthropi...se_converse_api': False}, input_type=dict]\n    For further information visit https://errors.pydantic.dev/2.11/v/value_error\n",
      "inputs": [
        "Download GEO dataset GSE291670"
      ],
      "responses": [],
      "duration_seconds": 0.005258,
      "final_status": null,
      "workspace_path": "/var/folders/hs/b1gtnn4x23s08f0b9z_ntbmm0000gn/T/lobster_test_test_geo_download_k7kac9el",
      "timestamp": "2025-08-13T13:10:37.004543"
    },
    "test_geo_download_with_qc": {
      "test_id": "test_geo_download_with_qc",
      "success": false,
      "error_message": "Test setup/execution failed: 1 validation error for ChatBedrock\n  Value error, Error raised by service:\n\nIf providing credentials, both aws_access_key_id and aws_secret_access_key must be specified. [type=value_error, input_value={'model_id': 'us.anthropi...se_converse_api': False}, input_type=dict]\n    For further information visit https://errors.pydantic.dev/2.11/v/value_error\nTraceback (most recent call last):\n  File \"/Users/tyo/GITHUB/lobster/tests/run_integration_tests.py\", line 105, in run_single_test\n    client = AgentClient(\n        workspace_path=workspace_dir,\n    ...<9 lines>...\n    }\n    )\n  File \"/Users/tyo/GITHUB/lobster/lobster/core/client.py\", line 62, in __init__\n    self.graph = create_bioinformatics_graph(\n                 ~~~~~~~~~~~~~~~~~~~~~~~~~~~^\n        data_manager=self.data_manager,\n        ^^^^^^^^^^^^^^^^^^^^^^^^^^^^^^^\n    ...<2 lines>...\n        manual_model_params=manual_model_params  # Placeholder for future manual model params\n        ^^^^^^^^^^^^^^^^^^^^^^^^^^^^^^^^^^^^^^^^^^^^^^^^^^^^^^^^^^^^^^^^^^^^^^^^^^^^^^^^^^^^^\n    )\n    ^\n  File \"/Users/tyo/GITHUB/lobster/lobster/agents/graph.py\", line 41, in create_bioinformatics_graph\n    supervisor_model = ChatBedrock(**model_params)\n  File \"/Users/tyo/GITHUB/lobster/.venv/lib/python3.13/site-packages/langchain_core/load/serializable.py\", line 130, in __init__\n    super().__init__(*args, **kwargs)\n    ~~~~~~~~~~~~~~~~^^^^^^^^^^^^^^^^^\n  File \"/Users/tyo/GITHUB/lobster/.venv/lib/python3.13/site-packages/pydantic/main.py\", line 253, in __init__\n    validated_self = self.__pydantic_validator__.validate_python(data, self_instance=self)\npydantic_core._pydantic_core.ValidationError: 1 validation error for ChatBedrock\n  Value error, Error raised by service:\n\nIf providing credentials, both aws_access_key_id and aws_secret_access_key must be specified. [type=value_error, input_value={'model_id': 'us.anthropi...se_converse_api': False}, input_type=dict]\n    For further information visit https://errors.pydantic.dev/2.11/v/value_error\n",
      "inputs": [
        "Download GEO dataset GSE291670 and do the quality control"
      ],
      "responses": [],
      "duration_seconds": 0.000544,
      "final_status": null,
      "workspace_path": "/var/folders/hs/b1gtnn4x23s08f0b9z_ntbmm0000gn/T/lobster_test_test_geo_download_with_qc_fkqzwfty",
      "timestamp": "2025-08-13T13:10:37.005767"
    },
    "test_geo_download_with_qc_umap": {
      "test_id": "test_geo_download_with_qc_umap",
      "success": false,
      "error_message": "Test setup/execution failed: 1 validation error for ChatBedrock\n  Value error, Error raised by service:\n\nIf providing credentials, both aws_access_key_id and aws_secret_access_key must be specified. [type=value_error, input_value={'model_id': 'us.anthropi...se_converse_api': False}, input_type=dict]\n    For further information visit https://errors.pydantic.dev/2.11/v/value_error\nTraceback (most recent call last):\n  File \"/Users/tyo/GITHUB/lobster/tests/run_integration_tests.py\", line 105, in run_single_test\n    client = AgentClient(\n        workspace_path=workspace_dir,\n    ...<9 lines>...\n    }\n    )\n  File \"/Users/tyo/GITHUB/lobster/lobster/core/client.py\", line 62, in __init__\n    self.graph = create_bioinformatics_graph(\n                 ~~~~~~~~~~~~~~~~~~~~~~~~~~~^\n        data_manager=self.data_manager,\n        ^^^^^^^^^^^^^^^^^^^^^^^^^^^^^^^\n    ...<2 lines>...\n        manual_model_params=manual_model_params  # Placeholder for future manual model params\n        ^^^^^^^^^^^^^^^^^^^^^^^^^^^^^^^^^^^^^^^^^^^^^^^^^^^^^^^^^^^^^^^^^^^^^^^^^^^^^^^^^^^^^\n    )\n    ^\n  File \"/Users/tyo/GITHUB/lobster/lobster/agents/graph.py\", line 41, in create_bioinformatics_graph\n    supervisor_model = ChatBedrock(**model_params)\n  File \"/Users/tyo/GITHUB/lobster/.venv/lib/python3.13/site-packages/langchain_core/load/serializable.py\", line 130, in __init__\n    super().__init__(*args, **kwargs)\n    ~~~~~~~~~~~~~~~~^^^^^^^^^^^^^^^^^\n  File \"/Users/tyo/GITHUB/lobster/.venv/lib/python3.13/site-packages/pydantic/main.py\", line 253, in __init__\n    validated_self = self.__pydantic_validator__.validate_python(data, self_instance=self)\npydantic_core._pydantic_core.ValidationError: 1 validation error for ChatBedrock\n  Value error, Error raised by service:\n\nIf providing credentials, both aws_access_key_id and aws_secret_access_key must be specified. [type=value_error, input_value={'model_id': 'us.anthropi...se_converse_api': False}, input_type=dict]\n    For further information visit https://errors.pydantic.dev/2.11/v/value_error\n",
      "inputs": [
        "Download GEO dataset GSE291670 and do the quality control",
        "Generate the UMAP with resolution 0.7"
      ],
      "responses": [],
      "duration_seconds": 0.000206,
      "final_status": null,
      "workspace_path": "/var/folders/hs/b1gtnn4x23s08f0b9z_ntbmm0000gn/T/lobster_test_test_geo_download_with_qc_umap_fy0y7fv4",
      "timestamp": "2025-08-13T13:10:37.007184"
    },
    "test_random_question_geo_download_with_qc": {
      "test_id": "test_random_question_geo_download_with_qc",
      "success": false,
      "error_message": "Test setup/execution failed: 1 validation error for ChatBedrock\n  Value error, Error raised by service:\n\nIf providing credentials, both aws_access_key_id and aws_secret_access_key must be specified. [type=value_error, input_value={'model_id': 'us.anthropi...se_converse_api': False}, input_type=dict]\n    For further information visit https://errors.pydantic.dev/2.11/v/value_error\nTraceback (most recent call last):\n  File \"/Users/tyo/GITHUB/lobster/tests/run_integration_tests.py\", line 105, in run_single_test\n    client = AgentClient(\n        workspace_path=workspace_dir,\n    ...<9 lines>...\n    }\n    )\n  File \"/Users/tyo/GITHUB/lobster/lobster/core/client.py\", line 62, in __init__\n    self.graph = create_bioinformatics_graph(\n                 ~~~~~~~~~~~~~~~~~~~~~~~~~~~^\n        data_manager=self.data_manager,\n        ^^^^^^^^^^^^^^^^^^^^^^^^^^^^^^^\n    ...<2 lines>...\n        manual_model_params=manual_model_params  # Placeholder for future manual model params\n        ^^^^^^^^^^^^^^^^^^^^^^^^^^^^^^^^^^^^^^^^^^^^^^^^^^^^^^^^^^^^^^^^^^^^^^^^^^^^^^^^^^^^^\n    )\n    ^\n  File \"/Users/tyo/GITHUB/lobster/lobster/agents/graph.py\", line 41, in create_bioinformatics_graph\n    supervisor_model = ChatBedrock(**model_params)\n  File \"/Users/tyo/GITHUB/lobster/.venv/lib/python3.13/site-packages/langchain_core/load/serializable.py\", line 130, in __init__\n    super().__init__(*args, **kwargs)\n    ~~~~~~~~~~~~~~~~^^^^^^^^^^^^^^^^^\n  File \"/Users/tyo/GITHUB/lobster/.venv/lib/python3.13/site-packages/pydantic/main.py\", line 253, in __init__\n    validated_self = self.__pydantic_validator__.validate_python(data, self_instance=self)\npydantic_core._pydantic_core.ValidationError: 1 validation error for ChatBedrock\n  Value error, Error raised by service:\n\nIf providing credentials, both aws_access_key_id and aws_secret_access_key must be specified. [type=value_error, input_value={'model_id': 'us.anthropi...se_converse_api': False}, input_type=dict]\n    For further information visit https://errors.pydantic.dev/2.11/v/value_error\n",
      "inputs": [
        "Hi how are you?",
        "Download GEO dataset GSE291670 and do the quality control",
        "Generate the UMAP with resolution 0.7"
      ],
      "responses": [],
      "duration_seconds": 0.000551,
      "final_status": null,
      "workspace_path": "/var/folders/hs/b1gtnn4x23s08f0b9z_ntbmm0000gn/T/lobster_test_test_random_question_geo_download_with_qc_x3zyi3l2",
      "timestamp": "2025-08-13T13:10:37.008578"
    },
    "test_simple_geo_query": {
      "test_id": "test_simple_geo_query",
      "success": false,
      "error_message": "Test setup/execution failed: 1 validation error for ChatBedrock\n  Value error, Error raised by service:\n\nIf providing credentials, both aws_access_key_id and aws_secret_access_key must be specified. [type=value_error, input_value={'model_id': 'us.anthropi...se_converse_api': False}, input_type=dict]\n    For further information visit https://errors.pydantic.dev/2.11/v/value_error\nTraceback (most recent call last):\n  File \"/Users/tyo/GITHUB/lobster/tests/run_integration_tests.py\", line 105, in run_single_test\n    client = AgentClient(\n        workspace_path=workspace_dir,\n    ...<9 lines>...\n    }\n    )\n  File \"/Users/tyo/GITHUB/lobster/lobster/core/client.py\", line 62, in __init__\n    self.graph = create_bioinformatics_graph(\n                 ~~~~~~~~~~~~~~~~~~~~~~~~~~~^\n        data_manager=self.data_manager,\n        ^^^^^^^^^^^^^^^^^^^^^^^^^^^^^^^\n    ...<2 lines>...\n        manual_model_params=manual_model_params  # Placeholder for future manual model params\n        ^^^^^^^^^^^^^^^^^^^^^^^^^^^^^^^^^^^^^^^^^^^^^^^^^^^^^^^^^^^^^^^^^^^^^^^^^^^^^^^^^^^^^\n    )\n    ^\n  File \"/Users/tyo/GITHUB/lobster/lobster/agents/graph.py\", line 41, in create_bioinformatics_graph\n    supervisor_model = ChatBedrock(**model_params)\n  File \"/Users/tyo/GITHUB/lobster/.venv/lib/python3.13/site-packages/langchain_core/load/serializable.py\", line 130, in __init__\n    super().__init__(*args, **kwargs)\n    ~~~~~~~~~~~~~~~~^^^^^^^^^^^^^^^^^\n  File \"/Users/tyo/GITHUB/lobster/.venv/lib/python3.13/site-packages/pydantic/main.py\", line 253, in __init__\n    validated_self = self.__pydantic_validator__.validate_python(data, self_instance=self)\npydantic_core._pydantic_core.ValidationError: 1 validation error for ChatBedrock\n  Value error, Error raised by service:\n\nIf providing credentials, both aws_access_key_id and aws_secret_access_key must be specified. [type=value_error, input_value={'model_id': 'us.anthropi...se_converse_api': False}, input_type=dict]\n    For further information visit https://errors.pydantic.dev/2.11/v/value_error\n",
      "inputs": [
        "Download GSE109564 from GEO"
      ],
      "responses": [],
      "duration_seconds": 0.000459,
      "final_status": null,
      "workspace_path": "/var/folders/hs/b1gtnn4x23s08f0b9z_ntbmm0000gn/T/lobster_test_test_simple_geo_query_v1xfuu9s",
      "timestamp": "2025-08-13T13:10:37.009636"
    },
    "test_full_analysis_workflow": {
      "test_id": "test_full_analysis_workflow",
      "success": false,
      "error_message": "Test setup/execution failed: 1 validation error for ChatBedrock\n  Value error, Error raised by service:\n\nIf providing credentials, both aws_access_key_id and aws_secret_access_key must be specified. [type=value_error, input_value={'model_id': 'us.anthropi...se_converse_api': False}, input_type=dict]\n    For further information visit https://errors.pydantic.dev/2.11/v/value_error\nTraceback (most recent call last):\n  File \"/Users/tyo/GITHUB/lobster/tests/run_integration_tests.py\", line 105, in run_single_test\n    client = AgentClient(\n        workspace_path=workspace_dir,\n    ...<9 lines>...\n    }\n    )\n  File \"/Users/tyo/GITHUB/lobster/lobster/core/client.py\", line 62, in __init__\n    self.graph = create_bioinformatics_graph(\n                 ~~~~~~~~~~~~~~~~~~~~~~~~~~~^\n        data_manager=self.data_manager,\n        ^^^^^^^^^^^^^^^^^^^^^^^^^^^^^^^\n    ...<2 lines>...\n        manual_model_params=manual_model_params  # Placeholder for future manual model params\n        ^^^^^^^^^^^^^^^^^^^^^^^^^^^^^^^^^^^^^^^^^^^^^^^^^^^^^^^^^^^^^^^^^^^^^^^^^^^^^^^^^^^^^\n    )\n    ^\n  File \"/Users/tyo/GITHUB/lobster/lobster/agents/graph.py\", line 41, in create_bioinformatics_graph\n    supervisor_model = ChatBedrock(**model_params)\n  File \"/Users/tyo/GITHUB/lobster/.venv/lib/python3.13/site-packages/langchain_core/load/serializable.py\", line 130, in __init__\n    super().__init__(*args, **kwargs)\n    ~~~~~~~~~~~~~~~~^^^^^^^^^^^^^^^^^\n  File \"/Users/tyo/GITHUB/lobster/.venv/lib/python3.13/site-packages/pydantic/main.py\", line 253, in __init__\n    validated_self = self.__pydantic_validator__.validate_python(data, self_instance=self)\npydantic_core._pydantic_core.ValidationError: 1 validation error for ChatBedrock\n  Value error, Error raised by service:\n\nIf providing credentials, both aws_access_key_id and aws_secret_access_key must be specified. [type=value_error, input_value={'model_id': 'us.anthropi...se_converse_api': False}, input_type=dict]\n    For further information visit https://errors.pydantic.dev/2.11/v/value_error\n",
      "inputs": [
        "Download GSE109564 from GEO and perform quality control",
        "Perform clustering using Leiden algorithm",
        "Create UMAP visualization",
        "Identify cell type markers"
      ],
      "responses": [],
      "duration_seconds": 0.000533,
      "final_status": null,
      "workspace_path": "/var/folders/hs/b1gtnn4x23s08f0b9z_ntbmm0000gn/T/lobster_test_test_full_analysis_workflow_rw8k8lgc",
      "timestamp": "2025-08-13T13:10:37.010746"
    },
    "test_specific_qc_parameters": {
      "test_id": "test_specific_qc_parameters",
      "success": false,
      "error_message": "Test setup/execution failed: 1 validation error for ChatBedrock\n  Value error, Error raised by service:\n\nIf providing credentials, both aws_access_key_id and aws_secret_access_key must be specified. [type=value_error, input_value={'model_id': 'us.anthropi...se_converse_api': False}, input_type=dict]\n    For further information visit https://errors.pydantic.dev/2.11/v/value_error\nTraceback (most recent call last):\n  File \"/Users/tyo/GITHUB/lobster/tests/run_integration_tests.py\", line 105, in run_single_test\n    client = AgentClient(\n        workspace_path=workspace_dir,\n    ...<9 lines>...\n    }\n    )\n  File \"/Users/tyo/GITHUB/lobster/lobster/core/client.py\", line 62, in __init__\n    self.graph = create_bioinformatics_graph(\n                 ~~~~~~~~~~~~~~~~~~~~~~~~~~~^\n        data_manager=self.data_manager,\n        ^^^^^^^^^^^^^^^^^^^^^^^^^^^^^^^\n    ...<2 lines>...\n        manual_model_params=manual_model_params  # Placeholder for future manual model params\n        ^^^^^^^^^^^^^^^^^^^^^^^^^^^^^^^^^^^^^^^^^^^^^^^^^^^^^^^^^^^^^^^^^^^^^^^^^^^^^^^^^^^^^\n    )\n    ^\n  File \"/Users/tyo/GITHUB/lobster/lobster/agents/graph.py\", line 41, in create_bioinformatics_graph\n    supervisor_model = ChatBedrock(**model_params)\n  File \"/Users/tyo/GITHUB/lobster/.venv/lib/python3.13/site-packages/langchain_core/load/serializable.py\", line 130, in __init__\n    super().__init__(*args, **kwargs)\n    ~~~~~~~~~~~~~~~~^^^^^^^^^^^^^^^^^\n  File \"/Users/tyo/GITHUB/lobster/.venv/lib/python3.13/site-packages/pydantic/main.py\", line 253, in __init__\n    validated_self = self.__pydantic_validator__.validate_python(data, self_instance=self)\npydantic_core._pydantic_core.ValidationError: 1 validation error for ChatBedrock\n  Value error, Error raised by service:\n\nIf providing credentials, both aws_access_key_id and aws_secret_access_key must be specified. [type=value_error, input_value={'model_id': 'us.anthropi...se_converse_api': False}, input_type=dict]\n    For further information visit https://errors.pydantic.dev/2.11/v/value_error\n",
      "inputs": [
        "Download GEO dataset GSE291670",
        "Perform quality control with mitochondrial gene threshold of 20% and minimum genes per cell of 200"
      ],
      "responses": [],
      "duration_seconds": 0.000426,
      "final_status": null,
      "workspace_path": "/var/folders/hs/b1gtnn4x23s08f0b9z_ntbmm0000gn/T/lobster_test_test_specific_qc_parameters_i5zmj0zx",
      "timestamp": "2025-08-13T13:10:37.011887"
    },
    "test_clustering_parameters": {
      "test_id": "test_clustering_parameters",
      "success": false,
      "error_message": "Test setup/execution failed: 1 validation error for ChatBedrock\n  Value error, Error raised by service:\n\nIf providing credentials, both aws_access_key_id and aws_secret_access_key must be specified. [type=value_error, input_value={'model_id': 'us.anthropi...se_converse_api': False}, input_type=dict]\n    For further information visit https://errors.pydantic.dev/2.11/v/value_error\nTraceback (most recent call last):\n  File \"/Users/tyo/GITHUB/lobster/tests/run_integration_tests.py\", line 105, in run_single_test\n    client = AgentClient(\n        workspace_path=workspace_dir,\n    ...<9 lines>...\n    }\n    )\n  File \"/Users/tyo/GITHUB/lobster/lobster/core/client.py\", line 62, in __init__\n    self.graph = create_bioinformatics_graph(\n                 ~~~~~~~~~~~~~~~~~~~~~~~~~~~^\n        data_manager=self.data_manager,\n        ^^^^^^^^^^^^^^^^^^^^^^^^^^^^^^^\n    ...<2 lines>...\n        manual_model_params=manual_model_params  # Placeholder for future manual model params\n        ^^^^^^^^^^^^^^^^^^^^^^^^^^^^^^^^^^^^^^^^^^^^^^^^^^^^^^^^^^^^^^^^^^^^^^^^^^^^^^^^^^^^^\n    )\n    ^\n  File \"/Users/tyo/GITHUB/lobster/lobster/agents/graph.py\", line 41, in create_bioinformatics_graph\n    supervisor_model = ChatBedrock(**model_params)\n  File \"/Users/tyo/GITHUB/lobster/.venv/lib/python3.13/site-packages/langchain_core/load/serializable.py\", line 130, in __init__\n    super().__init__(*args, **kwargs)\n    ~~~~~~~~~~~~~~~~^^^^^^^^^^^^^^^^^\n  File \"/Users/tyo/GITHUB/lobster/.venv/lib/python3.13/site-packages/pydantic/main.py\", line 253, in __init__\n    validated_self = self.__pydantic_validator__.validate_python(data, self_instance=self)\npydantic_core._pydantic_core.ValidationError: 1 validation error for ChatBedrock\n  Value error, Error raised by service:\n\nIf providing credentials, both aws_access_key_id and aws_secret_access_key must be specified. [type=value_error, input_value={'model_id': 'us.anthropi...se_converse_api': False}, input_type=dict]\n    For further information visit https://errors.pydantic.dev/2.11/v/value_error\n",
      "inputs": [
        "Download GSE109564 and do quality control",
        "Perform Leiden clustering with resolution 0.5",
        "Generate UMAP with 15 neighbors and minimum distance 0.3"
      ],
      "responses": [],
      "duration_seconds": 0.000539,
      "final_status": null,
      "workspace_path": "/var/folders/hs/b1gtnn4x23s08f0b9z_ntbmm0000gn/T/lobster_test_test_clustering_parameters_i7o6aeki",
      "timestamp": "2025-08-13T13:10:37.013796"
    },
    "test_differential_expression": {
      "test_id": "test_differential_expression",
      "success": false,
      "error_message": "Test setup/execution failed: 1 validation error for ChatBedrock\n  Value error, Error raised by service:\n\nIf providing credentials, both aws_access_key_id and aws_secret_access_key must be specified. [type=value_error, input_value={'model_id': 'us.anthropi...se_converse_api': False}, input_type=dict]\n    For further information visit https://errors.pydantic.dev/2.11/v/value_error\nTraceback (most recent call last):\n  File \"/Users/tyo/GITHUB/lobster/tests/run_integration_tests.py\", line 105, in run_single_test\n    client = AgentClient(\n        workspace_path=workspace_dir,\n    ...<9 lines>...\n    }\n    )\n  File \"/Users/tyo/GITHUB/lobster/lobster/core/client.py\", line 62, in __init__\n    self.graph = create_bioinformatics_graph(\n                 ~~~~~~~~~~~~~~~~~~~~~~~~~~~^\n        data_manager=self.data_manager,\n        ^^^^^^^^^^^^^^^^^^^^^^^^^^^^^^^\n    ...<2 lines>...\n        manual_model_params=manual_model_params  # Placeholder for future manual model params\n        ^^^^^^^^^^^^^^^^^^^^^^^^^^^^^^^^^^^^^^^^^^^^^^^^^^^^^^^^^^^^^^^^^^^^^^^^^^^^^^^^^^^^^\n    )\n    ^\n  File \"/Users/tyo/GITHUB/lobster/lobster/agents/graph.py\", line 41, in create_bioinformatics_graph\n    supervisor_model = ChatBedrock(**model_params)\n  File \"/Users/tyo/GITHUB/lobster/.venv/lib/python3.13/site-packages/langchain_core/load/serializable.py\", line 130, in __init__\n    super().__init__(*args, **kwargs)\n    ~~~~~~~~~~~~~~~~^^^^^^^^^^^^^^^^^\n  File \"/Users/tyo/GITHUB/lobster/.venv/lib/python3.13/site-packages/pydantic/main.py\", line 253, in __init__\n    validated_self = self.__pydantic_validator__.validate_python(data, self_instance=self)\npydantic_core._pydantic_core.ValidationError: 1 validation error for ChatBedrock\n  Value error, Error raised by service:\n\nIf providing credentials, both aws_access_key_id and aws_secret_access_key must be specified. [type=value_error, input_value={'model_id': 'us.anthropi...se_converse_api': False}, input_type=dict]\n    For further information visit https://errors.pydantic.dev/2.11/v/value_error\n",
      "inputs": [
        "Download GSE109564 from GEO",
        "Perform quality control and clustering",
        "Find differentially expressed genes between clusters 0 and 1"
      ],
      "responses": [],
      "duration_seconds": 0.000532,
      "final_status": null,
      "workspace_path": "/var/folders/hs/b1gtnn4x23s08f0b9z_ntbmm0000gn/T/lobster_test_test_differential_expression_vihdbiz6",
      "timestamp": "2025-08-13T13:10:37.015025"
    },
    "test_pathway_analysis": {
      "test_id": "test_pathway_analysis",
      "success": false,
      "error_message": "Test setup/execution failed: 1 validation error for ChatBedrock\n  Value error, Error raised by service:\n\nIf providing credentials, both aws_access_key_id and aws_secret_access_key must be specified. [type=value_error, input_value={'model_id': 'us.anthropi...se_converse_api': False}, input_type=dict]\n    For further information visit https://errors.pydantic.dev/2.11/v/value_error\nTraceback (most recent call last):\n  File \"/Users/tyo/GITHUB/lobster/tests/run_integration_tests.py\", line 105, in run_single_test\n    client = AgentClient(\n        workspace_path=workspace_dir,\n    ...<9 lines>...\n    }\n    )\n  File \"/Users/tyo/GITHUB/lobster/lobster/core/client.py\", line 62, in __init__\n    self.graph = create_bioinformatics_graph(\n                 ~~~~~~~~~~~~~~~~~~~~~~~~~~~^\n        data_manager=self.data_manager,\n        ^^^^^^^^^^^^^^^^^^^^^^^^^^^^^^^\n    ...<2 lines>...\n        manual_model_params=manual_model_params  # Placeholder for future manual model params\n        ^^^^^^^^^^^^^^^^^^^^^^^^^^^^^^^^^^^^^^^^^^^^^^^^^^^^^^^^^^^^^^^^^^^^^^^^^^^^^^^^^^^^^\n    )\n    ^\n  File \"/Users/tyo/GITHUB/lobster/lobster/agents/graph.py\", line 41, in create_bioinformatics_graph\n    supervisor_model = ChatBedrock(**model_params)\n  File \"/Users/tyo/GITHUB/lobster/.venv/lib/python3.13/site-packages/langchain_core/load/serializable.py\", line 130, in __init__\n    super().__init__(*args, **kwargs)\n    ~~~~~~~~~~~~~~~~^^^^^^^^^^^^^^^^^\n  File \"/Users/tyo/GITHUB/lobster/.venv/lib/python3.13/site-packages/pydantic/main.py\", line 253, in __init__\n    validated_self = self.__pydantic_validator__.validate_python(data, self_instance=self)\npydantic_core._pydantic_core.ValidationError: 1 validation error for ChatBedrock\n  Value error, Error raised by service:\n\nIf providing credentials, both aws_access_key_id and aws_secret_access_key must be specified. [type=value_error, input_value={'model_id': 'us.anthropi...se_converse_api': False}, input_type=dict]\n    For further information visit https://errors.pydantic.dev/2.11/v/value_error\n",
      "inputs": [
        "Download GSE291670 and perform complete analysis",
        "Perform GO enrichment analysis on the top differentially expressed genes"
      ],
      "responses": [],
      "duration_seconds": 0.000205,
      "final_status": null,
      "workspace_path": "/var/folders/hs/b1gtnn4x23s08f0b9z_ntbmm0000gn/T/lobster_test_test_pathway_analysis__jnqkoal",
      "timestamp": "2025-08-13T13:10:37.015809"
    },
    "test_cell_annotation": {
      "test_id": "test_cell_annotation",
      "success": false,
      "error_message": "Test setup/execution failed: 1 validation error for ChatBedrock\n  Value error, Error raised by service:\n\nIf providing credentials, both aws_access_key_id and aws_secret_access_key must be specified. [type=value_error, input_value={'model_id': 'us.anthropi...se_converse_api': False}, input_type=dict]\n    For further information visit https://errors.pydantic.dev/2.11/v/value_error\nTraceback (most recent call last):\n  File \"/Users/tyo/GITHUB/lobster/tests/run_integration_tests.py\", line 105, in run_single_test\n    client = AgentClient(\n        workspace_path=workspace_dir,\n    ...<9 lines>...\n    }\n    )\n  File \"/Users/tyo/GITHUB/lobster/lobster/core/client.py\", line 62, in __init__\n    self.graph = create_bioinformatics_graph(\n                 ~~~~~~~~~~~~~~~~~~~~~~~~~~~^\n        data_manager=self.data_manager,\n        ^^^^^^^^^^^^^^^^^^^^^^^^^^^^^^^\n    ...<2 lines>...\n        manual_model_params=manual_model_params  # Placeholder for future manual model params\n        ^^^^^^^^^^^^^^^^^^^^^^^^^^^^^^^^^^^^^^^^^^^^^^^^^^^^^^^^^^^^^^^^^^^^^^^^^^^^^^^^^^^^^\n    )\n    ^\n  File \"/Users/tyo/GITHUB/lobster/lobster/agents/graph.py\", line 41, in create_bioinformatics_graph\n    supervisor_model = ChatBedrock(**model_params)\n  File \"/Users/tyo/GITHUB/lobster/.venv/lib/python3.13/site-packages/langchain_core/load/serializable.py\", line 130, in __init__\n    super().__init__(*args, **kwargs)\n    ~~~~~~~~~~~~~~~~^^^^^^^^^^^^^^^^^\n  File \"/Users/tyo/GITHUB/lobster/.venv/lib/python3.13/site-packages/pydantic/main.py\", line 253, in __init__\n    validated_self = self.__pydantic_validator__.validate_python(data, self_instance=self)\npydantic_core._pydantic_core.ValidationError: 1 validation error for ChatBedrock\n  Value error, Error raised by service:\n\nIf providing credentials, both aws_access_key_id and aws_secret_access_key must be specified. [type=value_error, input_value={'model_id': 'us.anthropi...se_converse_api': False}, input_type=dict]\n    For further information visit https://errors.pydantic.dev/2.11/v/value_error\n",
      "inputs": [
        "Download GSE109564 from GEO",
        "Perform quality control and clustering",
        "Annotate cell types using marker genes"
      ],
      "responses": [],
      "duration_seconds": 0.00051,
      "final_status": null,
      "workspace_path": "/var/folders/hs/b1gtnn4x23s08f0b9z_ntbmm0000gn/T/lobster_test_test_cell_annotation_3ny0ac9c",
      "timestamp": "2025-08-13T13:10:37.016907"
    },
    "test_literature_integration": {
      "test_id": "test_literature_integration",
      "success": false,
      "error_message": "Test setup/execution failed: 1 validation error for ChatBedrock\n  Value error, Error raised by service:\n\nIf providing credentials, both aws_access_key_id and aws_secret_access_key must be specified. [type=value_error, input_value={'model_id': 'us.anthropi...se_converse_api': False}, input_type=dict]\n    For further information visit https://errors.pydantic.dev/2.11/v/value_error\nTraceback (most recent call last):\n  File \"/Users/tyo/GITHUB/lobster/tests/run_integration_tests.py\", line 105, in run_single_test\n    client = AgentClient(\n        workspace_path=workspace_dir,\n    ...<9 lines>...\n    }\n    )\n  File \"/Users/tyo/GITHUB/lobster/lobster/core/client.py\", line 62, in __init__\n    self.graph = create_bioinformatics_graph(\n                 ~~~~~~~~~~~~~~~~~~~~~~~~~~~^\n        data_manager=self.data_manager,\n        ^^^^^^^^^^^^^^^^^^^^^^^^^^^^^^^\n    ...<2 lines>...\n        manual_model_params=manual_model_params  # Placeholder for future manual model params\n        ^^^^^^^^^^^^^^^^^^^^^^^^^^^^^^^^^^^^^^^^^^^^^^^^^^^^^^^^^^^^^^^^^^^^^^^^^^^^^^^^^^^^^\n    )\n    ^\n  File \"/Users/tyo/GITHUB/lobster/lobster/agents/graph.py\", line 41, in create_bioinformatics_graph\n    supervisor_model = ChatBedrock(**model_params)\n  File \"/Users/tyo/GITHUB/lobster/.venv/lib/python3.13/site-packages/langchain_core/load/serializable.py\", line 130, in __init__\n    super().__init__(*args, **kwargs)\n    ~~~~~~~~~~~~~~~~^^^^^^^^^^^^^^^^^\n  File \"/Users/tyo/GITHUB/lobster/.venv/lib/python3.13/site-packages/pydantic/main.py\", line 253, in __init__\n    validated_self = self.__pydantic_validator__.validate_python(data, self_instance=self)\npydantic_core._pydantic_core.ValidationError: 1 validation error for ChatBedrock\n  Value error, Error raised by service:\n\nIf providing credentials, both aws_access_key_id and aws_secret_access_key must be specified. [type=value_error, input_value={'model_id': 'us.anthropi...se_converse_api': False}, input_type=dict]\n    For further information visit https://errors.pydantic.dev/2.11/v/value_error\n",
      "inputs": [
        "Find optimal parameters for single-cell RNA-seq quality control from recent literature",
        "Download GSE291670 and apply those parameters"
      ],
      "responses": [],
      "duration_seconds": 0.000563,
      "final_status": null,
      "workspace_path": "/var/folders/hs/b1gtnn4x23s08f0b9z_ntbmm0000gn/T/lobster_test_test_literature_integration_b4f5k7ay",
      "timestamp": "2025-08-13T13:10:37.018193"
    },
    "test_multiple_datasets": {
      "test_id": "test_multiple_datasets",
      "success": false,
      "error_message": "Test setup/execution failed: 1 validation error for ChatBedrock\n  Value error, Error raised by service:\n\nIf providing credentials, both aws_access_key_id and aws_secret_access_key must be specified. [type=value_error, input_value={'model_id': 'us.anthropi...se_converse_api': False}, input_type=dict]\n    For further information visit https://errors.pydantic.dev/2.11/v/value_error\nTraceback (most recent call last):\n  File \"/Users/tyo/GITHUB/lobster/tests/run_integration_tests.py\", line 105, in run_single_test\n    client = AgentClient(\n        workspace_path=workspace_dir,\n    ...<9 lines>...\n    }\n    )\n  File \"/Users/tyo/GITHUB/lobster/lobster/core/client.py\", line 62, in __init__\n    self.graph = create_bioinformatics_graph(\n                 ~~~~~~~~~~~~~~~~~~~~~~~~~~~^\n        data_manager=self.data_manager,\n        ^^^^^^^^^^^^^^^^^^^^^^^^^^^^^^^\n    ...<2 lines>...\n        manual_model_params=manual_model_params  # Placeholder for future manual model params\n        ^^^^^^^^^^^^^^^^^^^^^^^^^^^^^^^^^^^^^^^^^^^^^^^^^^^^^^^^^^^^^^^^^^^^^^^^^^^^^^^^^^^^^\n    )\n    ^\n  File \"/Users/tyo/GITHUB/lobster/lobster/agents/graph.py\", line 41, in create_bioinformatics_graph\n    supervisor_model = ChatBedrock(**model_params)\n  File \"/Users/tyo/GITHUB/lobster/.venv/lib/python3.13/site-packages/langchain_core/load/serializable.py\", line 130, in __init__\n    super().__init__(*args, **kwargs)\n    ~~~~~~~~~~~~~~~~^^^^^^^^^^^^^^^^^\n  File \"/Users/tyo/GITHUB/lobster/.venv/lib/python3.13/site-packages/pydantic/main.py\", line 253, in __init__\n    validated_self = self.__pydantic_validator__.validate_python(data, self_instance=self)\npydantic_core._pydantic_core.ValidationError: 1 validation error for ChatBedrock\n  Value error, Error raised by service:\n\nIf providing credentials, both aws_access_key_id and aws_secret_access_key must be specified. [type=value_error, input_value={'model_id': 'us.anthropi...se_converse_api': False}, input_type=dict]\n    For further information visit https://errors.pydantic.dev/2.11/v/value_error\n",
      "inputs": [
        "Download GSE109564 from GEO",
        "Also download GSE291670",
        "Compare the quality metrics between these two datasets"
      ],
      "responses": [],
      "duration_seconds": 0.000205,
      "final_status": null,
      "workspace_path": "/var/folders/hs/b1gtnn4x23s08f0b9z_ntbmm0000gn/T/lobster_test_test_multiple_datasets_webj1s4k",
      "timestamp": "2025-08-13T13:10:37.018958"
    },
    "test_error_handling_invalid_geo": {
      "test_id": "test_error_handling_invalid_geo",
      "success": false,
      "error_message": "Test setup/execution failed: 1 validation error for ChatBedrock\n  Value error, Error raised by service:\n\nIf providing credentials, both aws_access_key_id and aws_secret_access_key must be specified. [type=value_error, input_value={'model_id': 'us.anthropi...se_converse_api': False}, input_type=dict]\n    For further information visit https://errors.pydantic.dev/2.11/v/value_error\nTraceback (most recent call last):\n  File \"/Users/tyo/GITHUB/lobster/tests/run_integration_tests.py\", line 105, in run_single_test\n    client = AgentClient(\n        workspace_path=workspace_dir,\n    ...<9 lines>...\n    }\n    )\n  File \"/Users/tyo/GITHUB/lobster/lobster/core/client.py\", line 62, in __init__\n    self.graph = create_bioinformatics_graph(\n                 ~~~~~~~~~~~~~~~~~~~~~~~~~~~^\n        data_manager=self.data_manager,\n        ^^^^^^^^^^^^^^^^^^^^^^^^^^^^^^^\n    ...<2 lines>...\n        manual_model_params=manual_model_params  # Placeholder for future manual model params\n        ^^^^^^^^^^^^^^^^^^^^^^^^^^^^^^^^^^^^^^^^^^^^^^^^^^^^^^^^^^^^^^^^^^^^^^^^^^^^^^^^^^^^^\n    )\n    ^\n  File \"/Users/tyo/GITHUB/lobster/lobster/agents/graph.py\", line 41, in create_bioinformatics_graph\n    supervisor_model = ChatBedrock(**model_params)\n  File \"/Users/tyo/GITHUB/lobster/.venv/lib/python3.13/site-packages/langchain_core/load/serializable.py\", line 130, in __init__\n    super().__init__(*args, **kwargs)\n    ~~~~~~~~~~~~~~~~^^^^^^^^^^^^^^^^^\n  File \"/Users/tyo/GITHUB/lobster/.venv/lib/python3.13/site-packages/pydantic/main.py\", line 253, in __init__\n    validated_self = self.__pydantic_validator__.validate_python(data, self_instance=self)\npydantic_core._pydantic_core.ValidationError: 1 validation error for ChatBedrock\n  Value error, Error raised by service:\n\nIf providing credentials, both aws_access_key_id and aws_secret_access_key must be specified. [type=value_error, input_value={'model_id': 'us.anthropi...se_converse_api': False}, input_type=dict]\n    For further information visit https://errors.pydantic.dev/2.11/v/value_error\n",
      "inputs": [
        "Download GEO dataset GSE999999999"
      ],
      "responses": [],
      "duration_seconds": 0.000421,
      "final_status": null,
      "workspace_path": "/var/folders/hs/b1gtnn4x23s08f0b9z_ntbmm0000gn/T/lobster_test_test_error_handling_invalid_geo_l10xrii7",
      "timestamp": "2025-08-13T13:10:37.020005"
    },
    "test_conversational_with_analysis": {
      "test_id": "test_conversational_with_analysis",
      "success": false,
      "error_message": "Test setup/execution failed: 1 validation error for ChatBedrock\n  Value error, Error raised by service:\n\nIf providing credentials, both aws_access_key_id and aws_secret_access_key must be specified. [type=value_error, input_value={'model_id': 'us.anthropi...se_converse_api': False}, input_type=dict]\n    For further information visit https://errors.pydantic.dev/2.11/v/value_error\nTraceback (most recent call last):\n  File \"/Users/tyo/GITHUB/lobster/tests/run_integration_tests.py\", line 105, in run_single_test\n    client = AgentClient(\n        workspace_path=workspace_dir,\n    ...<9 lines>...\n    }\n    )\n  File \"/Users/tyo/GITHUB/lobster/lobster/core/client.py\", line 62, in __init__\n    self.graph = create_bioinformatics_graph(\n                 ~~~~~~~~~~~~~~~~~~~~~~~~~~~^\n        data_manager=self.data_manager,\n        ^^^^^^^^^^^^^^^^^^^^^^^^^^^^^^^\n    ...<2 lines>...\n        manual_model_params=manual_model_params  # Placeholder for future manual model params\n        ^^^^^^^^^^^^^^^^^^^^^^^^^^^^^^^^^^^^^^^^^^^^^^^^^^^^^^^^^^^^^^^^^^^^^^^^^^^^^^^^^^^^^\n    )\n    ^\n  File \"/Users/tyo/GITHUB/lobster/lobster/agents/graph.py\", line 41, in create_bioinformatics_graph\n    supervisor_model = ChatBedrock(**model_params)\n  File \"/Users/tyo/GITHUB/lobster/.venv/lib/python3.13/site-packages/langchain_core/load/serializable.py\", line 130, in __init__\n    super().__init__(*args, **kwargs)\n    ~~~~~~~~~~~~~~~~^^^^^^^^^^^^^^^^^\n  File \"/Users/tyo/GITHUB/lobster/.venv/lib/python3.13/site-packages/pydantic/main.py\", line 253, in __init__\n    validated_self = self.__pydantic_validator__.validate_python(data, self_instance=self)\npydantic_core._pydantic_core.ValidationError: 1 validation error for ChatBedrock\n  Value error, Error raised by service:\n\nIf providing credentials, both aws_access_key_id and aws_secret_access_key must be specified. [type=value_error, input_value={'model_id': 'us.anthropi...se_converse_api': False}, input_type=dict]\n    For further information visit https://errors.pydantic.dev/2.11/v/value_error\n",
      "inputs": [
        "Hello, I need help with single-cell analysis",
        "I want to analyze GSE109564",
        "Please download it and show me the basic statistics",
        "Now perform quality control",
        "What cell types might be present based on the clustering?"
      ],
      "responses": [],
      "duration_seconds": 0.000342,
      "final_status": null,
      "workspace_path": "/var/folders/hs/b1gtnn4x23s08f0b9z_ntbmm0000gn/T/lobster_test_test_conversational_with_analysis_wozlwimb",
      "timestamp": "2025-08-13T13:10:37.020906"
    },
    "test_advanced_visualization": {
      "test_id": "test_advanced_visualization",
      "success": false,
      "error_message": "Test setup/execution failed: 1 validation error for ChatBedrock\n  Value error, Error raised by service:\n\nIf providing credentials, both aws_access_key_id and aws_secret_access_key must be specified. [type=value_error, input_value={'model_id': 'us.anthropi...se_converse_api': False}, input_type=dict]\n    For further information visit https://errors.pydantic.dev/2.11/v/value_error\nTraceback (most recent call last):\n  File \"/Users/tyo/GITHUB/lobster/tests/run_integration_tests.py\", line 105, in run_single_test\n    client = AgentClient(\n        workspace_path=workspace_dir,\n    ...<9 lines>...\n    }\n    )\n  File \"/Users/tyo/GITHUB/lobster/lobster/core/client.py\", line 62, in __init__\n    self.graph = create_bioinformatics_graph(\n                 ~~~~~~~~~~~~~~~~~~~~~~~~~~~^\n        data_manager=self.data_manager,\n        ^^^^^^^^^^^^^^^^^^^^^^^^^^^^^^^\n    ...<2 lines>...\n        manual_model_params=manual_model_params  # Placeholder for future manual model params\n        ^^^^^^^^^^^^^^^^^^^^^^^^^^^^^^^^^^^^^^^^^^^^^^^^^^^^^^^^^^^^^^^^^^^^^^^^^^^^^^^^^^^^^\n    )\n    ^\n  File \"/Users/tyo/GITHUB/lobster/lobster/agents/graph.py\", line 41, in create_bioinformatics_graph\n    supervisor_model = ChatBedrock(**model_params)\n  File \"/Users/tyo/GITHUB/lobster/.venv/lib/python3.13/site-packages/langchain_core/load/serializable.py\", line 130, in __init__\n    super().__init__(*args, **kwargs)\n    ~~~~~~~~~~~~~~~~^^^^^^^^^^^^^^^^^\n  File \"/Users/tyo/GITHUB/lobster/.venv/lib/python3.13/site-packages/pydantic/main.py\", line 253, in __init__\n    validated_self = self.__pydantic_validator__.validate_python(data, self_instance=self)\npydantic_core._pydantic_core.ValidationError: 1 validation error for ChatBedrock\n  Value error, Error raised by service:\n\nIf providing credentials, both aws_access_key_id and aws_secret_access_key must be specified. [type=value_error, input_value={'model_id': 'us.anthropi...se_converse_api': False}, input_type=dict]\n    For further information visit https://errors.pydantic.dev/2.11/v/value_error\n",
      "inputs": [
        "Download GSE291670 and perform quality control",
        "Create violin plots for QC metrics",
        "Generate feature plots for top variable genes",
        "Create a heatmap of marker genes for each cluster"
      ],
      "responses": [],
      "duration_seconds": 0.000226,
      "final_status": null,
      "workspace_path": "/var/folders/hs/b1gtnn4x23s08f0b9z_ntbmm0000gn/T/lobster_test_test_advanced_visualization_hauaxo40",
      "timestamp": "2025-08-13T13:10:37.021978"
    },
    "test_batch_effect_analysis": {
      "test_id": "test_batch_effect_analysis",
      "success": false,
      "error_message": "Test setup/execution failed: 1 validation error for ChatBedrock\n  Value error, Error raised by service:\n\nIf providing credentials, both aws_access_key_id and aws_secret_access_key must be specified. [type=value_error, input_value={'model_id': 'us.anthropi...se_converse_api': False}, input_type=dict]\n    For further information visit https://errors.pydantic.dev/2.11/v/value_error\nTraceback (most recent call last):\n  File \"/Users/tyo/GITHUB/lobster/tests/run_integration_tests.py\", line 105, in run_single_test\n    client = AgentClient(\n        workspace_path=workspace_dir,\n    ...<9 lines>...\n    }\n    )\n  File \"/Users/tyo/GITHUB/lobster/lobster/core/client.py\", line 62, in __init__\n    self.graph = create_bioinformatics_graph(\n                 ~~~~~~~~~~~~~~~~~~~~~~~~~~~^\n        data_manager=self.data_manager,\n        ^^^^^^^^^^^^^^^^^^^^^^^^^^^^^^^\n    ...<2 lines>...\n        manual_model_params=manual_model_params  # Placeholder for future manual model params\n        ^^^^^^^^^^^^^^^^^^^^^^^^^^^^^^^^^^^^^^^^^^^^^^^^^^^^^^^^^^^^^^^^^^^^^^^^^^^^^^^^^^^^^\n    )\n    ^\n  File \"/Users/tyo/GITHUB/lobster/lobster/agents/graph.py\", line 41, in create_bioinformatics_graph\n    supervisor_model = ChatBedrock(**model_params)\n  File \"/Users/tyo/GITHUB/lobster/.venv/lib/python3.13/site-packages/langchain_core/load/serializable.py\", line 130, in __init__\n    super().__init__(*args, **kwargs)\n    ~~~~~~~~~~~~~~~~^^^^^^^^^^^^^^^^^\n  File \"/Users/tyo/GITHUB/lobster/.venv/lib/python3.13/site-packages/pydantic/main.py\", line 253, in __init__\n    validated_self = self.__pydantic_validator__.validate_python(data, self_instance=self)\npydantic_core._pydantic_core.ValidationError: 1 validation error for ChatBedrock\n  Value error, Error raised by service:\n\nIf providing credentials, both aws_access_key_id and aws_secret_access_key must be specified. [type=value_error, input_value={'model_id': 'us.anthropi...se_converse_api': False}, input_type=dict]\n    For further information visit https://errors.pydantic.dev/2.11/v/value_error\n",
      "inputs": [
        "Download GSE109564 from GEO",
        "Check for batch effects in the data",
        "If present, suggest correction methods"
      ],
      "responses": [],
      "duration_seconds": 0.000348,
      "final_status": null,
      "workspace_path": "/var/folders/hs/b1gtnn4x23s08f0b9z_ntbmm0000gn/T/lobster_test_test_batch_effect_analysis_kuuxuhli",
      "timestamp": "2025-08-13T13:10:37.023417"
    },
    "test_doublet_detection": {
      "test_id": "test_doublet_detection",
      "success": false,
      "error_message": "Test setup/execution failed: 1 validation error for ChatBedrock\n  Value error, Error raised by service:\n\nIf providing credentials, both aws_access_key_id and aws_secret_access_key must be specified. [type=value_error, input_value={'model_id': 'us.anthropi...se_converse_api': False}, input_type=dict]\n    For further information visit https://errors.pydantic.dev/2.11/v/value_error\nTraceback (most recent call last):\n  File \"/Users/tyo/GITHUB/lobster/tests/run_integration_tests.py\", line 105, in run_single_test\n    client = AgentClient(\n        workspace_path=workspace_dir,\n    ...<9 lines>...\n    }\n    )\n  File \"/Users/tyo/GITHUB/lobster/lobster/core/client.py\", line 62, in __init__\n    self.graph = create_bioinformatics_graph(\n                 ~~~~~~~~~~~~~~~~~~~~~~~~~~~^\n        data_manager=self.data_manager,\n        ^^^^^^^^^^^^^^^^^^^^^^^^^^^^^^^\n    ...<2 lines>...\n        manual_model_params=manual_model_params  # Placeholder for future manual model params\n        ^^^^^^^^^^^^^^^^^^^^^^^^^^^^^^^^^^^^^^^^^^^^^^^^^^^^^^^^^^^^^^^^^^^^^^^^^^^^^^^^^^^^^\n    )\n    ^\n  File \"/Users/tyo/GITHUB/lobster/lobster/agents/graph.py\", line 41, in create_bioinformatics_graph\n    supervisor_model = ChatBedrock(**model_params)\n  File \"/Users/tyo/GITHUB/lobster/.venv/lib/python3.13/site-packages/langchain_core/load/serializable.py\", line 130, in __init__\n    super().__init__(*args, **kwargs)\n    ~~~~~~~~~~~~~~~~^^^^^^^^^^^^^^^^^\n  File \"/Users/tyo/GITHUB/lobster/.venv/lib/python3.13/site-packages/pydantic/main.py\", line 253, in __init__\n    validated_self = self.__pydantic_validator__.validate_python(data, self_instance=self)\npydantic_core._pydantic_core.ValidationError: 1 validation error for ChatBedrock\n  Value error, Error raised by service:\n\nIf providing credentials, both aws_access_key_id and aws_secret_access_key must be specified. [type=value_error, input_value={'model_id': 'us.anthropi...se_converse_api': False}, input_type=dict]\n    For further information visit https://errors.pydantic.dev/2.11/v/value_error\n",
      "inputs": [
        "Download GSE291670",
        "Perform doublet detection using scrublet",
        "Remove doublets and proceed with quality control"
      ],
      "responses": [],
      "duration_seconds": 0.000203,
      "final_status": null,
      "workspace_path": "/var/folders/hs/b1gtnn4x23s08f0b9z_ntbmm0000gn/T/lobster_test_test_doublet_detection_5ar4cjjg",
      "timestamp": "2025-08-13T13:10:37.024196"
    },
    "test_custom_gene_sets": {
      "test_id": "test_custom_gene_sets",
      "success": false,
      "error_message": "Test setup/execution failed: 1 validation error for ChatBedrock\n  Value error, Error raised by service:\n\nIf providing credentials, both aws_access_key_id and aws_secret_access_key must be specified. [type=value_error, input_value={'model_id': 'us.anthropi...se_converse_api': False}, input_type=dict]\n    For further information visit https://errors.pydantic.dev/2.11/v/value_error\nTraceback (most recent call last):\n  File \"/Users/tyo/GITHUB/lobster/tests/run_integration_tests.py\", line 105, in run_single_test\n    client = AgentClient(\n        workspace_path=workspace_dir,\n    ...<9 lines>...\n    }\n    )\n  File \"/Users/tyo/GITHUB/lobster/lobster/core/client.py\", line 62, in __init__\n    self.graph = create_bioinformatics_graph(\n                 ~~~~~~~~~~~~~~~~~~~~~~~~~~~^\n        data_manager=self.data_manager,\n        ^^^^^^^^^^^^^^^^^^^^^^^^^^^^^^^\n    ...<2 lines>...\n        manual_model_params=manual_model_params  # Placeholder for future manual model params\n        ^^^^^^^^^^^^^^^^^^^^^^^^^^^^^^^^^^^^^^^^^^^^^^^^^^^^^^^^^^^^^^^^^^^^^^^^^^^^^^^^^^^^^\n    )\n    ^\n  File \"/Users/tyo/GITHUB/lobster/lobster/agents/graph.py\", line 41, in create_bioinformatics_graph\n    supervisor_model = ChatBedrock(**model_params)\n  File \"/Users/tyo/GITHUB/lobster/.venv/lib/python3.13/site-packages/langchain_core/load/serializable.py\", line 130, in __init__\n    super().__init__(*args, **kwargs)\n    ~~~~~~~~~~~~~~~~^^^^^^^^^^^^^^^^^\n  File \"/Users/tyo/GITHUB/lobster/.venv/lib/python3.13/site-packages/pydantic/main.py\", line 253, in __init__\n    validated_self = self.__pydantic_validator__.validate_python(data, self_instance=self)\npydantic_core._pydantic_core.ValidationError: 1 validation error for ChatBedrock\n  Value error, Error raised by service:\n\nIf providing credentials, both aws_access_key_id and aws_secret_access_key must be specified. [type=value_error, input_value={'model_id': 'us.anthropi...se_converse_api': False}, input_type=dict]\n    For further information visit https://errors.pydantic.dev/2.11/v/value_error\n",
      "inputs": [
        "Download GSE109564 and perform basic analysis",
        "Calculate scores for T cell markers: CD3D, CD3E, CD4, CD8A",
        "Identify which clusters express these markers"
      ],
      "responses": [],
      "duration_seconds": 0.000234,
      "final_status": null,
      "workspace_path": "/var/folders/hs/b1gtnn4x23s08f0b9z_ntbmm0000gn/T/lobster_test_test_custom_gene_sets_n9or13jw",
      "timestamp": "2025-08-13T13:10:37.025104"
    },
    "test_trajectory_analysis": {
      "test_id": "test_trajectory_analysis",
      "success": false,
      "error_message": "Test setup/execution failed: 1 validation error for ChatBedrock\n  Value error, Error raised by service:\n\nIf providing credentials, both aws_access_key_id and aws_secret_access_key must be specified. [type=value_error, input_value={'model_id': 'us.anthropi...se_converse_api': False}, input_type=dict]\n    For further information visit https://errors.pydantic.dev/2.11/v/value_error\nTraceback (most recent call last):\n  File \"/Users/tyo/GITHUB/lobster/tests/run_integration_tests.py\", line 105, in run_single_test\n    client = AgentClient(\n        workspace_path=workspace_dir,\n    ...<9 lines>...\n    }\n    )\n  File \"/Users/tyo/GITHUB/lobster/lobster/core/client.py\", line 62, in __init__\n    self.graph = create_bioinformatics_graph(\n                 ~~~~~~~~~~~~~~~~~~~~~~~~~~~^\n        data_manager=self.data_manager,\n        ^^^^^^^^^^^^^^^^^^^^^^^^^^^^^^^\n    ...<2 lines>...\n        manual_model_params=manual_model_params  # Placeholder for future manual model params\n        ^^^^^^^^^^^^^^^^^^^^^^^^^^^^^^^^^^^^^^^^^^^^^^^^^^^^^^^^^^^^^^^^^^^^^^^^^^^^^^^^^^^^^\n    )\n    ^\n  File \"/Users/tyo/GITHUB/lobster/lobster/agents/graph.py\", line 41, in create_bioinformatics_graph\n    supervisor_model = ChatBedrock(**model_params)\n  File \"/Users/tyo/GITHUB/lobster/.venv/lib/python3.13/site-packages/langchain_core/load/serializable.py\", line 130, in __init__\n    super().__init__(*args, **kwargs)\n    ~~~~~~~~~~~~~~~~^^^^^^^^^^^^^^^^^\n  File \"/Users/tyo/GITHUB/lobster/.venv/lib/python3.13/site-packages/pydantic/main.py\", line 253, in __init__\n    validated_self = self.__pydantic_validator__.validate_python(data, self_instance=self)\npydantic_core._pydantic_core.ValidationError: 1 validation error for ChatBedrock\n  Value error, Error raised by service:\n\nIf providing credentials, both aws_access_key_id and aws_secret_access_key must be specified. [type=value_error, input_value={'model_id': 'us.anthropi...se_converse_api': False}, input_type=dict]\n    For further information visit https://errors.pydantic.dev/2.11/v/value_error\n",
      "inputs": [
        "Download GSE291670 from GEO",
        "Perform quality control and clustering",
        "Suggest trajectory analysis methods for this dataset"
      ],
      "responses": [],
      "duration_seconds": 0.000237,
      "final_status": null,
      "workspace_path": "/var/folders/hs/b1gtnn4x23s08f0b9z_ntbmm0000gn/T/lobster_test_test_trajectory_analysis_ot0pa4bi",
      "timestamp": "2025-08-13T13:10:37.025897"
    },
    "test_integration_methods": {
      "test_id": "test_integration_methods",
      "success": false,
      "error_message": "Test setup/execution failed: 1 validation error for ChatBedrock\n  Value error, Error raised by service:\n\nIf providing credentials, both aws_access_key_id and aws_secret_access_key must be specified. [type=value_error, input_value={'model_id': 'us.anthropi...se_converse_api': False}, input_type=dict]\n    For further information visit https://errors.pydantic.dev/2.11/v/value_error\nTraceback (most recent call last):\n  File \"/Users/tyo/GITHUB/lobster/tests/run_integration_tests.py\", line 105, in run_single_test\n    client = AgentClient(\n        workspace_path=workspace_dir,\n    ...<9 lines>...\n    }\n    )\n  File \"/Users/tyo/GITHUB/lobster/lobster/core/client.py\", line 62, in __init__\n    self.graph = create_bioinformatics_graph(\n                 ~~~~~~~~~~~~~~~~~~~~~~~~~~~^\n        data_manager=self.data_manager,\n        ^^^^^^^^^^^^^^^^^^^^^^^^^^^^^^^\n    ...<2 lines>...\n        manual_model_params=manual_model_params  # Placeholder for future manual model params\n        ^^^^^^^^^^^^^^^^^^^^^^^^^^^^^^^^^^^^^^^^^^^^^^^^^^^^^^^^^^^^^^^^^^^^^^^^^^^^^^^^^^^^^\n    )\n    ^\n  File \"/Users/tyo/GITHUB/lobster/lobster/agents/graph.py\", line 41, in create_bioinformatics_graph\n    supervisor_model = ChatBedrock(**model_params)\n  File \"/Users/tyo/GITHUB/lobster/.venv/lib/python3.13/site-packages/langchain_core/load/serializable.py\", line 130, in __init__\n    super().__init__(*args, **kwargs)\n    ~~~~~~~~~~~~~~~~^^^^^^^^^^^^^^^^^\n  File \"/Users/tyo/GITHUB/lobster/.venv/lib/python3.13/site-packages/pydantic/main.py\", line 253, in __init__\n    validated_self = self.__pydantic_validator__.validate_python(data, self_instance=self)\npydantic_core._pydantic_core.ValidationError: 1 validation error for ChatBedrock\n  Value error, Error raised by service:\n\nIf providing credentials, both aws_access_key_id and aws_secret_access_key must be specified. [type=value_error, input_value={'model_id': 'us.anthropi...se_converse_api': False}, input_type=dict]\n    For further information visit https://errors.pydantic.dev/2.11/v/value_error\n",
      "inputs": [
        "I have multiple single-cell datasets that need integration",
        "What are the best methods for batch correction?",
        "Download GSE109564 as an example and show preprocessing steps"
      ],
      "responses": [],
      "duration_seconds": 0.000261,
      "final_status": null,
      "workspace_path": "/var/folders/hs/b1gtnn4x23s08f0b9z_ntbmm0000gn/T/lobster_test_test_integration_methods_6ffuaql1",
      "timestamp": "2025-08-13T13:10:37.028006"
    },
    "test_export_functionality": {
      "test_id": "test_export_functionality",
      "success": false,
      "error_message": "Test setup/execution failed: 1 validation error for ChatBedrock\n  Value error, Error raised by service:\n\nIf providing credentials, both aws_access_key_id and aws_secret_access_key must be specified. [type=value_error, input_value={'model_id': 'us.anthropi...se_converse_api': False}, input_type=dict]\n    For further information visit https://errors.pydantic.dev/2.11/v/value_error\nTraceback (most recent call last):\n  File \"/Users/tyo/GITHUB/lobster/tests/run_integration_tests.py\", line 105, in run_single_test\n    client = AgentClient(\n        workspace_path=workspace_dir,\n    ...<9 lines>...\n    }\n    )\n  File \"/Users/tyo/GITHUB/lobster/lobster/core/client.py\", line 62, in __init__\n    self.graph = create_bioinformatics_graph(\n                 ~~~~~~~~~~~~~~~~~~~~~~~~~~~^\n        data_manager=self.data_manager,\n        ^^^^^^^^^^^^^^^^^^^^^^^^^^^^^^^\n    ...<2 lines>...\n        manual_model_params=manual_model_params  # Placeholder for future manual model params\n        ^^^^^^^^^^^^^^^^^^^^^^^^^^^^^^^^^^^^^^^^^^^^^^^^^^^^^^^^^^^^^^^^^^^^^^^^^^^^^^^^^^^^^\n    )\n    ^\n  File \"/Users/tyo/GITHUB/lobster/lobster/agents/graph.py\", line 41, in create_bioinformatics_graph\n    supervisor_model = ChatBedrock(**model_params)\n  File \"/Users/tyo/GITHUB/lobster/.venv/lib/python3.13/site-packages/langchain_core/load/serializable.py\", line 130, in __init__\n    super().__init__(*args, **kwargs)\n    ~~~~~~~~~~~~~~~~^^^^^^^^^^^^^^^^^\n  File \"/Users/tyo/GITHUB/lobster/.venv/lib/python3.13/site-packages/pydantic/main.py\", line 253, in __init__\n    validated_self = self.__pydantic_validator__.validate_python(data, self_instance=self)\npydantic_core._pydantic_core.ValidationError: 1 validation error for ChatBedrock\n  Value error, Error raised by service:\n\nIf providing credentials, both aws_access_key_id and aws_secret_access_key must be specified. [type=value_error, input_value={'model_id': 'us.anthropi...se_converse_api': False}, input_type=dict]\n    For further information visit https://errors.pydantic.dev/2.11/v/value_error\n",
      "inputs": [
        "Download GSE291670 and perform complete analysis",
        "Export all results including plots and processed data"
      ],
      "responses": [],
      "duration_seconds": 0.000739,
      "final_status": null,
      "workspace_path": "/var/folders/hs/b1gtnn4x23s08f0b9z_ntbmm0000gn/T/lobster_test_test_export_functionality_9wnp8djj",
      "timestamp": "2025-08-13T13:10:37.029441"
    },
    "test_parameter_optimization": {
      "test_id": "test_parameter_optimization",
      "success": false,
      "error_message": "Test setup/execution failed: 1 validation error for ChatBedrock\n  Value error, Error raised by service:\n\nIf providing credentials, both aws_access_key_id and aws_secret_access_key must be specified. [type=value_error, input_value={'model_id': 'us.anthropi...se_converse_api': False}, input_type=dict]\n    For further information visit https://errors.pydantic.dev/2.11/v/value_error\nTraceback (most recent call last):\n  File \"/Users/tyo/GITHUB/lobster/tests/run_integration_tests.py\", line 105, in run_single_test\n    client = AgentClient(\n        workspace_path=workspace_dir,\n    ...<9 lines>...\n    }\n    )\n  File \"/Users/tyo/GITHUB/lobster/lobster/core/client.py\", line 62, in __init__\n    self.graph = create_bioinformatics_graph(\n                 ~~~~~~~~~~~~~~~~~~~~~~~~~~~^\n        data_manager=self.data_manager,\n        ^^^^^^^^^^^^^^^^^^^^^^^^^^^^^^^\n    ...<2 lines>...\n        manual_model_params=manual_model_params  # Placeholder for future manual model params\n        ^^^^^^^^^^^^^^^^^^^^^^^^^^^^^^^^^^^^^^^^^^^^^^^^^^^^^^^^^^^^^^^^^^^^^^^^^^^^^^^^^^^^^\n    )\n    ^\n  File \"/Users/tyo/GITHUB/lobster/lobster/agents/graph.py\", line 41, in create_bioinformatics_graph\n    supervisor_model = ChatBedrock(**model_params)\n  File \"/Users/tyo/GITHUB/lobster/.venv/lib/python3.13/site-packages/langchain_core/load/serializable.py\", line 130, in __init__\n    super().__init__(*args, **kwargs)\n    ~~~~~~~~~~~~~~~~^^^^^^^^^^^^^^^^^\n  File \"/Users/tyo/GITHUB/lobster/.venv/lib/python3.13/site-packages/pydantic/main.py\", line 253, in __init__\n    validated_self = self.__pydantic_validator__.validate_python(data, self_instance=self)\npydantic_core._pydantic_core.ValidationError: 1 validation error for ChatBedrock\n  Value error, Error raised by service:\n\nIf providing credentials, both aws_access_key_id and aws_secret_access_key must be specified. [type=value_error, input_value={'model_id': 'us.anthropi...se_converse_api': False}, input_type=dict]\n    For further information visit https://errors.pydantic.dev/2.11/v/value_error\n",
      "inputs": [
        "Download GSE109564",
        "Test different clustering resolutions: 0.3, 0.5, 0.8",
        "Which resolution gives the most biologically meaningful clusters?"
      ],
      "responses": [],
      "duration_seconds": 0.000519,
      "final_status": null,
      "workspace_path": "/var/folders/hs/b1gtnn4x23s08f0b9z_ntbmm0000gn/T/lobster_test_test_parameter_optimization_aqnhrlln",
      "timestamp": "2025-08-13T13:10:37.030611"
    },
    "test_statistical_analysis": {
      "test_id": "test_statistical_analysis",
      "success": false,
      "error_message": "Test setup/execution failed: 1 validation error for ChatBedrock\n  Value error, Error raised by service:\n\nIf providing credentials, both aws_access_key_id and aws_secret_access_key must be specified. [type=value_error, input_value={'model_id': 'us.anthropi...se_converse_api': False}, input_type=dict]\n    For further information visit https://errors.pydantic.dev/2.11/v/value_error\nTraceback (most recent call last):\n  File \"/Users/tyo/GITHUB/lobster/tests/run_integration_tests.py\", line 105, in run_single_test\n    client = AgentClient(\n        workspace_path=workspace_dir,\n    ...<9 lines>...\n    }\n    )\n  File \"/Users/tyo/GITHUB/lobster/lobster/core/client.py\", line 62, in __init__\n    self.graph = create_bioinformatics_graph(\n                 ~~~~~~~~~~~~~~~~~~~~~~~~~~~^\n        data_manager=self.data_manager,\n        ^^^^^^^^^^^^^^^^^^^^^^^^^^^^^^^\n    ...<2 lines>...\n        manual_model_params=manual_model_params  # Placeholder for future manual model params\n        ^^^^^^^^^^^^^^^^^^^^^^^^^^^^^^^^^^^^^^^^^^^^^^^^^^^^^^^^^^^^^^^^^^^^^^^^^^^^^^^^^^^^^\n    )\n    ^\n  File \"/Users/tyo/GITHUB/lobster/lobster/agents/graph.py\", line 41, in create_bioinformatics_graph\n    supervisor_model = ChatBedrock(**model_params)\n  File \"/Users/tyo/GITHUB/lobster/.venv/lib/python3.13/site-packages/langchain_core/load/serializable.py\", line 130, in __init__\n    super().__init__(*args, **kwargs)\n    ~~~~~~~~~~~~~~~~^^^^^^^^^^^^^^^^^\n  File \"/Users/tyo/GITHUB/lobster/.venv/lib/python3.13/site-packages/pydantic/main.py\", line 253, in __init__\n    validated_self = self.__pydantic_validator__.validate_python(data, self_instance=self)\npydantic_core._pydantic_core.ValidationError: 1 validation error for ChatBedrock\n  Value error, Error raised by service:\n\nIf providing credentials, both aws_access_key_id and aws_secret_access_key must be specified. [type=value_error, input_value={'model_id': 'us.anthropi...se_converse_api': False}, input_type=dict]\n    For further information visit https://errors.pydantic.dev/2.11/v/value_error\n",
      "inputs": [
        "Download GSE291670 and perform quality control",
        "Calculate statistical significance of differentially expressed genes",
        "Apply multiple testing correction"
      ],
      "responses": [],
      "duration_seconds": 0.000223,
      "final_status": null,
      "workspace_path": "/var/folders/hs/b1gtnn4x23s08f0b9z_ntbmm0000gn/T/lobster_test_test_statistical_analysis_kmwje4hd",
      "timestamp": "2025-08-13T13:10:37.031472"
    },
    "test_data_interpretation": {
      "test_id": "test_data_interpretation",
      "success": false,
      "error_message": "Test setup/execution failed: 1 validation error for ChatBedrock\n  Value error, Error raised by service:\n\nIf providing credentials, both aws_access_key_id and aws_secret_access_key must be specified. [type=value_error, input_value={'model_id': 'us.anthropi...se_converse_api': False}, input_type=dict]\n    For further information visit https://errors.pydantic.dev/2.11/v/value_error\nTraceback (most recent call last):\n  File \"/Users/tyo/GITHUB/lobster/tests/run_integration_tests.py\", line 105, in run_single_test\n    client = AgentClient(\n        workspace_path=workspace_dir,\n    ...<9 lines>...\n    }\n    )\n  File \"/Users/tyo/GITHUB/lobster/lobster/core/client.py\", line 62, in __init__\n    self.graph = create_bioinformatics_graph(\n                 ~~~~~~~~~~~~~~~~~~~~~~~~~~~^\n        data_manager=self.data_manager,\n        ^^^^^^^^^^^^^^^^^^^^^^^^^^^^^^^\n    ...<2 lines>...\n        manual_model_params=manual_model_params  # Placeholder for future manual model params\n        ^^^^^^^^^^^^^^^^^^^^^^^^^^^^^^^^^^^^^^^^^^^^^^^^^^^^^^^^^^^^^^^^^^^^^^^^^^^^^^^^^^^^^\n    )\n    ^\n  File \"/Users/tyo/GITHUB/lobster/lobster/agents/graph.py\", line 41, in create_bioinformatics_graph\n    supervisor_model = ChatBedrock(**model_params)\n  File \"/Users/tyo/GITHUB/lobster/.venv/lib/python3.13/site-packages/langchain_core/load/serializable.py\", line 130, in __init__\n    super().__init__(*args, **kwargs)\n    ~~~~~~~~~~~~~~~~^^^^^^^^^^^^^^^^^\n  File \"/Users/tyo/GITHUB/lobster/.venv/lib/python3.13/site-packages/pydantic/main.py\", line 253, in __init__\n    validated_self = self.__pydantic_validator__.validate_python(data, self_instance=self)\npydantic_core._pydantic_core.ValidationError: 1 validation error for ChatBedrock\n  Value error, Error raised by service:\n\nIf providing credentials, both aws_access_key_id and aws_secret_access_key must be specified. [type=value_error, input_value={'model_id': 'us.anthropi...se_converse_api': False}, input_type=dict]\n    For further information visit https://errors.pydantic.dev/2.11/v/value_error\n",
      "inputs": [
        "Download GSE109564 from GEO",
        "Perform complete analysis",
        "Interpret the biological significance of the findings",
        "Suggest follow-up experiments"
      ],
      "responses": [],
      "duration_seconds": 0.00042,
      "final_status": null,
      "workspace_path": "/var/folders/hs/b1gtnn4x23s08f0b9z_ntbmm0000gn/T/lobster_test_test_data_interpretation_1rv8fkbh",
      "timestamp": "2025-08-13T13:10:37.032803"
    },
    "test_troubleshooting": {
      "test_id": "test_troubleshooting",
      "success": false,
      "error_message": "Test setup/execution failed: 1 validation error for ChatBedrock\n  Value error, Error raised by service:\n\nIf providing credentials, both aws_access_key_id and aws_secret_access_key must be specified. [type=value_error, input_value={'model_id': 'us.anthropi...se_converse_api': False}, input_type=dict]\n    For further information visit https://errors.pydantic.dev/2.11/v/value_error\nTraceback (most recent call last):\n  File \"/Users/tyo/GITHUB/lobster/tests/run_integration_tests.py\", line 105, in run_single_test\n    client = AgentClient(\n        workspace_path=workspace_dir,\n    ...<9 lines>...\n    }\n    )\n  File \"/Users/tyo/GITHUB/lobster/lobster/core/client.py\", line 62, in __init__\n    self.graph = create_bioinformatics_graph(\n                 ~~~~~~~~~~~~~~~~~~~~~~~~~~~^\n        data_manager=self.data_manager,\n        ^^^^^^^^^^^^^^^^^^^^^^^^^^^^^^^\n    ...<2 lines>...\n        manual_model_params=manual_model_params  # Placeholder for future manual model params\n        ^^^^^^^^^^^^^^^^^^^^^^^^^^^^^^^^^^^^^^^^^^^^^^^^^^^^^^^^^^^^^^^^^^^^^^^^^^^^^^^^^^^^^\n    )\n    ^\n  File \"/Users/tyo/GITHUB/lobster/lobster/agents/graph.py\", line 41, in create_bioinformatics_graph\n    supervisor_model = ChatBedrock(**model_params)\n  File \"/Users/tyo/GITHUB/lobster/.venv/lib/python3.13/site-packages/langchain_core/load/serializable.py\", line 130, in __init__\n    super().__init__(*args, **kwargs)\n    ~~~~~~~~~~~~~~~~^^^^^^^^^^^^^^^^^\n  File \"/Users/tyo/GITHUB/lobster/.venv/lib/python3.13/site-packages/pydantic/main.py\", line 253, in __init__\n    validated_self = self.__pydantic_validator__.validate_python(data, self_instance=self)\npydantic_core._pydantic_core.ValidationError: 1 validation error for ChatBedrock\n  Value error, Error raised by service:\n\nIf providing credentials, both aws_access_key_id and aws_secret_access_key must be specified. [type=value_error, input_value={'model_id': 'us.anthropi...se_converse_api': False}, input_type=dict]\n    For further information visit https://errors.pydantic.dev/2.11/v/value_error\n",
      "inputs": [
        "Download GSE291670",
        "The quality control shows many low-quality cells, what should I do?",
        "Apply stricter filtering and re-analyze"
      ],
      "responses": [],
      "duration_seconds": 0.000643,
      "final_status": null,
      "workspace_path": "/var/folders/hs/b1gtnn4x23s08f0b9z_ntbmm0000gn/T/lobster_test_test_troubleshooting_7p7ho51t",
      "timestamp": "2025-08-13T13:10:37.034250"
    },
    "test_comparison_analysis": {
      "test_id": "test_comparison_analysis",
      "success": false,
      "error_message": "Test setup/execution failed: 1 validation error for ChatBedrock\n  Value error, Error raised by service:\n\nIf providing credentials, both aws_access_key_id and aws_secret_access_key must be specified. [type=value_error, input_value={'model_id': 'us.anthropi...se_converse_api': False}, input_type=dict]\n    For further information visit https://errors.pydantic.dev/2.11/v/value_error\nTraceback (most recent call last):\n  File \"/Users/tyo/GITHUB/lobster/tests/run_integration_tests.py\", line 105, in run_single_test\n    client = AgentClient(\n        workspace_path=workspace_dir,\n    ...<9 lines>...\n    }\n    )\n  File \"/Users/tyo/GITHUB/lobster/lobster/core/client.py\", line 62, in __init__\n    self.graph = create_bioinformatics_graph(\n                 ~~~~~~~~~~~~~~~~~~~~~~~~~~~^\n        data_manager=self.data_manager,\n        ^^^^^^^^^^^^^^^^^^^^^^^^^^^^^^^\n    ...<2 lines>...\n        manual_model_params=manual_model_params  # Placeholder for future manual model params\n        ^^^^^^^^^^^^^^^^^^^^^^^^^^^^^^^^^^^^^^^^^^^^^^^^^^^^^^^^^^^^^^^^^^^^^^^^^^^^^^^^^^^^^\n    )\n    ^\n  File \"/Users/tyo/GITHUB/lobster/lobster/agents/graph.py\", line 41, in create_bioinformatics_graph\n    supervisor_model = ChatBedrock(**model_params)\n  File \"/Users/tyo/GITHUB/lobster/.venv/lib/python3.13/site-packages/langchain_core/load/serializable.py\", line 130, in __init__\n    super().__init__(*args, **kwargs)\n    ~~~~~~~~~~~~~~~~^^^^^^^^^^^^^^^^^\n  File \"/Users/tyo/GITHUB/lobster/.venv/lib/python3.13/site-packages/pydantic/main.py\", line 253, in __init__\n    validated_self = self.__pydantic_validator__.validate_python(data, self_instance=self)\npydantic_core._pydantic_core.ValidationError: 1 validation error for ChatBedrock\n  Value error, Error raised by service:\n\nIf providing credentials, both aws_access_key_id and aws_secret_access_key must be specified. [type=value_error, input_value={'model_id': 'us.anthropi...se_converse_api': False}, input_type=dict]\n    For further information visit https://errors.pydantic.dev/2.11/v/value_error\n",
      "inputs": [
        "Download GSE109564",
        "Perform analysis with default parameters",
        "Now repeat with more stringent quality control",
        "Compare the results and explain differences"
      ],
      "responses": [],
      "duration_seconds": 0.000489,
      "final_status": null,
      "workspace_path": "/var/folders/hs/b1gtnn4x23s08f0b9z_ntbmm0000gn/T/lobster_test_test_comparison_analysis_nznq_qmt",
      "timestamp": "2025-08-13T13:10:37.035434"
    }
  }
}